<?xml version="1.0" encoding="utf-8"?>
<!-- This URDF was automatically created by SolidWorks to URDF Exporter! Originally created by Stephen Brawner (brawner@gmail.com) 
     Commit Version: 1.6.0-4-g7f85cfe  Build Version: 1.6.7995.38578
     For more information, please see http://wiki.ros.org/sw_urdf_exporter -->
<robot name="roboticarm8">
  <link name="world"/>
	<joint name="base_joint" type="fixed">
	<parent link="world"/>
	<child link="base_link"/>
	<origin rpy="0 0 0" xyz="0.0 0.0 0.0"/>
</joint>
  <link name="base_link">
    <inertial>
      <origin
        xyz="4.4244E-07 -0.00074499 0.022029"
        rpy="0 0 0" />
      <mass
        value="0.11625" />
      <inertia ixx="0.00016739" ixy="4.1579E-10" ixz="9.7912E-10" iyy="0.00015904" iyz="-4.2508E-06" izz="0.00025906" />
    </inertial>
    <visual>
      <origin xyz="0 0 0" rpy="0 0 0" />
      <geometry>
        <mesh filename="package://roboticarm8/meshes/base_link.STL" />
      </geometry>
      <material name="">
        <color rgba="1 1 1 1" />
      </material>
    </visual>
    <collision>
      <origin xyz="0 0 0" rpy="0 0 0" />
      <geometry>
        <mesh filename="package://roboticarm8/meshes/base_link.STL" />
      </geometry>
    </collision>
  </link>
  <link name="base_cap">
    <inertial>
      <origin xyz="-0.0061894 -0.002266 0.014457" rpy="0 0 0" />
      <mass value="0.06091" />
      <inertia ixx="4.5144E-05" ixy="5.8496E-06" ixz="7.5901E-06" iyy="4.378E-05" iyz="-1.7088E-06" izz="5.4306E-05" />
    </inertial>
    <visual>
      <origin xyz="0 0 0" rpy="0 0 0" />
      <geometry>
        <mesh filename="package://roboticarm8/meshes/base_cap.STL" />
      </geometry>
      <material name="">
        <color rgba="1 1 1 1" />
      </material>
    </visual>
    <collision>
      <origin xyz="0 0 0" rpy="0 0 0" />
      <geometry>
        <mesh filename="package://roboticarm8/meshes/base_cap.STL" />
      </geometry>
    </collision>
  </link>
  <joint name="base_cap_joint_1" type="revolute">
    <origin xyz="0 0 0.055" rpy="0 0 0" />
    <parent link="base_link" />
    <child link="base_cap" />
    <axis xyz="0 0 1" />
    <limit lower="0" upper="6.2832" effort="200" velocity="3" />
  </joint>
  <link name="link_1">
    <inertial>
      <origin xyz="0.017557 -0.031633 0.044541" rpy="0 0 0" />
      <mass value="0.084015" />
      <inertia ixx="0.00013661" ixy="2.5538E-05" ixz="-3.0902E-05" iyy="0.00010631" iyz="5.4095E-05" izz="6.4211E-05" />
    </inertial>
    <visual>
      <origin xyz="0 0 0" rpy="0 0 0" />
      <geometry>
        <mesh filename="package://roboticarm8/meshes/link_1.STL" />
      </geometry>
      <material
        name="">
        <color
          rgba="1 1 1 1" />
      </material>
    </visual>
    <collision>
      <origin
        xyz="0 0 0"
        rpy="0 0 0" />
      <geometry>
        <mesh
          filename="package://roboticarm8/meshes/link_1.STL" />
      </geometry>
    </collision>
  </link>
  <joint
    name="link_1_joint_2"
    type="revolute">
    <origin
      xyz="-0.0096866 0.01782 0.037393"
      rpy="0.66219 0.33288 0.24945" />
    <parent
      link="base_cap" />
    <child
      link="link_1" />
    <axis
      xyz="-0.87164 -0.49015 0" />
    <limit
      lower="-0.15"
      upper="0.75"
      effort="200"
      velocity="3" />
  </joint>
  <link
    name="link_2">
    <inertial>
      <origin
        xyz="-0.041542 -0.026316 0.025468"
        rpy="0 0 0" />
      <mass
        value="0.11707" />
      <inertia
        ixx="0.00015287"
        ixy="-3.7344E-05"
        ixz="6.1179E-05"
        iyy="0.00014273"
        iyz="4.6611E-05"
        izz="0.00012419" />
    </inertial>
    <visual>
      <origin
        xyz="0 0 0"
        rpy="0 0 0" />
      <geometry>
        <mesh
          filename="package://roboticarm8/meshes/link_2.STL" />
      </geometry>
      <material
        name="">
        <color
          rgba="1 1 1 1" />
      </material>
    </visual>
    <collision>
      <origin
        xyz="0 0 0"
        rpy="0 0 0" />
      <geometry>
        <mesh
          filename="package://roboticarm8/meshes/link_2.STL" />
      </geometry>
    </collision>
  </link>
  <joint
    name="link_2_joint_3"
    type="revolute">
    <origin
      xyz="0.035169 -0.06254 0.088589"
      rpy="-2.1909 -0.41317 0" />
    <parent
      link="link_1" />
    <child
      link="link_2" />
    <axis
      xyz="-0.79829 0 -0.60227" />
    <limit
      lower="-2"
      upper="0.15"
      effort="200"
      velocity="3" />
  </joint>
  <link
    name="link_3">
    <inertial>
      <origin
        xyz="-0.0074458 0.024676 0.010025"
        rpy="0 0 0" />
      <mass
        value="0.033212" />
      <inertia
        ixx="2.2028E-05"
        ixy="5.0871E-06"
        ixz="-6.7647E-09"
        iyy="1.4414E-05"
        iyz="2.1224E-08"
        izz="1.5317E-05" />
    </inertial>
    <visual>
      <origin
        xyz="0 0 0"
        rpy="0 0 0" />
      <geometry>
        <mesh
          filename="package://roboticarm8/meshes/link_3.STL" />
      </geometry>
      <material
        name="">
        <color
          rgba="1 1 1 1" />
      </material>
    </visual>
    <collision>
      <origin
        xyz="0 0 0"
        rpy="0 0 0" />
      <geometry>
        <mesh
          filename="package://roboticarm8/meshes/link_3.STL" />
      </geometry>
    </collision>
  </link>
  <joint
    name="link_3_joint_4"
    type="revolute">
    <origin
      xyz="-0.083626 -0.054825 0.080956"
      rpy="2.0043 -0.12047 0.25406" />
    <parent
      link="link_2" />
    <child
      link="link_3" />
    <axis
      xyz="-0.54286 0.83982 0" />
    <limit
      lower="0"
      upper="3.1416"
      effort="200"
      velocity="3" />
  </joint>
  <link
    name="link_4">
    <inertial>
      <origin
        xyz="-0.010128 -0.0020305 0.02133"
        rpy="0 0 0" />
      <mass
        value="0.033861" />
      <inertia
        ixx="2.6821E-05"
        ixy="-9.2733E-07"
        ixz="6.9404E-06"
        iyy="2.9083E-05"
        iyz="3.3459E-06"
        izz="1.0614E-05" />
    </inertial>
    <visual>
      <origin
        xyz="0 0 0"
        rpy="0 0 0" />
      <geometry>
        <mesh
          filename="package://roboticarm8/meshes/link_4.STL" />
      </geometry>
      <material
        name="">
        <color
          rgba="1 1 1 1" />
      </material>
    </visual>
    <collision>
      <origin
        xyz="0 0 0"
        rpy="0 0 0" />
      <geometry>
        <mesh
          filename="package://roboticarm8/meshes/link_4.STL" />
      </geometry>
    </collision>
  </link>
  <joint
    name="link_4_joint_5"
    type="revolute">
    <origin
      xyz="6.9976E-05 0.044102 0.01"
      rpy="3.1416 0 0" />
    <parent
      link="link_3" />
    <child
      link="link_4" />
    <axis
      xyz="-0.83982 0.54286 0" />
    <limit
      lower="-3.2"
      upper="0.55"
      effort="200"
      velocity="3" />
  </joint>
  <link
    name="gear_1">
    <inertial>
      <origin
        xyz="0.00032186 0.002437 0.0028562"
        rpy="0 0 0" />
      <mass
        value="0.0022834" />
      <inertia
        ixx="2.4763E-07"
        ixy="3.6369E-08"
        ixz="2.5127E-08"
        iyy="1.8109E-07"
        iyz="-6.9201E-08"
        izz="1.124E-07" />
    </inertial>
    <visual>
      <origin
        xyz="0 0 0"
        rpy="0 0 0" />
      <geometry>
        <mesh
          filename="package://roboticarm8/meshes/gear_1.STL" />
      </geometry>
      <material
        name="">
        <color
          rgba="1 1 1 1" />
      </material>
    </visual>
    <collision>
      <origin
        xyz="0 0 0"
        rpy="0 0 0" />
      <geometry>
        <mesh
          filename="package://roboticarm8/meshes/gear_1.STL" />
      </geometry>
    </collision>
  </link>
  <joint
    name="gear_1_joint_6"
    type="revolute">
    <origin
      xyz="-0.012677 -0.0043084 0.049"
      rpy="1.5708 0.48809 0.99696" />
    <parent
      link="link_4" />
    <child
      link="gear_1" />
    <axis
      xyz="-0.88323 -0.46894 0" />
    <limit
      lower="-0.75"
      upper="0.01"
      effort="100"
      velocity="3" />
  </joint>
  <link
    name="link_5">
    <inertial>
      <origin
        xyz="-0.01861 0.011593 -0.0094413"
        rpy="0 0 0" />
      <mass
        value="0.0015553" />
      <inertia
        ixx="1.9426E-07"
        ixy="9.4345E-08"
        ixz="-7.1583E-09"
        iyy="6.6655E-08"
        iyz="1.3482E-08"
        izz="2.3012E-07" />
    </inertial>
    <visual>
      <origin
        xyz="0 0 0"
        rpy="0 0 0" />
      <geometry>
        <mesh
          filename="package://roboticarm8/meshes/link_5.STL" />
      </geometry>
      <material
        name="">
        <color
          rgba="1 1 1 1" />
      </material>
    </visual>
    <collision>
      <origin
        xyz="0 0 0"
        rpy="0 0 0" />
      <geometry>
        <mesh
          filename="package://roboticarm8/meshes/link_5.STL" />
      </geometry>
    </collision>
  </link>
  <joint
    name="link_5_joint_6"
    type="fixed">
    <origin
      xyz="-0.0047678 0.018576 0.026603"
      rpy="0 0 0" />
    <parent
      link="gear_1" />
    <child
      link="link_5" />
    <axis
      xyz="0 0 0" />
    <limit
      lower="0"
      upper="1"
      effort="100"
      velocity="3" />
  </joint>
  <link
    name="grip_1">
    <inertial>
      <origin
        xyz="-0.017372 0.015659 0.0021786"
        rpy="0 0 0" />
      <mass
        value="0.014256" />
      <inertia
        ixx="3.7464E-06"
        ixy="1.4458E-06"
        ixz="-1.2722E-07"
        iyy="1.7909E-06"
        iyz="2.3962E-07"
        izz="3.7283E-06" />
    </inertial>
    <visual>
      <origin
        xyz="0 0 0"
        rpy="0 0 0" />
      <geometry>
        <mesh
          filename="package://roboticarm8/meshes/grip_1.STL" />
      </geometry>
      <material
        name="">
        <color
          rgba="1 1 1 1" />
      </material>
    </visual>
    <collision>
      <origin
        xyz="0 0 0"
        rpy="0 0 0" />
      <geometry>
        <mesh
          filename="package://roboticarm8/meshes/grip_1.STL" />
      </geometry>
    </collision>
  </link>
  <joint
    name="grip_1_joint_7"
    type="fixed">
    <origin
      xyz="-0.020707 0.032603 -0.010831"
      rpy="0 0 0" />
    <parent
      link="link_5" />
    <child
      link="grip_1" />
    <axis
      xyz="0 0 0" />
    <limit
      lower="0"
      upper="6.28319"
      effort="100"
      velocity="3" />
  </joint>
  <link
    name="gear_2">
    <inertial>
      <origin
        xyz="-0.0002612 -0.0035016 0.0013753"
        rpy="0 0 0" />
      <mass
        value="0.0022836" />
      <inertia
        ixx="2.3308E-07"
        ixy="-6.7816E-08"
        ixz="2.2266E-08"
        iyy="1.1566E-07"
        iyz="5.1877E-08"
        izz="1.9277E-07" />
    </inertial>
    <visual>
      <origin
        xyz="0 0 0"
        rpy="0 0 0" />
      <geometry>
        <mesh
          filename="package://roboticarm8/meshes/gear_2.STL" />
      </geometry>
      <material
        name="">
        <color
          rgba="1 1 1 1" />
      </material>
    </visual>
    <collision>
      <origin
        xyz="0 0 0"
        rpy="0 0 0" />
      <geometry>
        <mesh
          filename="package://roboticarm8/meshes/gear_2.STL" />
      </geometry>
    </collision>
  </link>
  <joint
    name="gear_2_joint_8"
    type="revolute">
    <origin
      xyz="-0.032413 0.0084488 0.049"
      rpy="-1.5755 0.49303 0.99475" />
    <parent
      link="link_4" />
    <child
      link="gear_2" />
    <axis
      xyz="0.8809 -0.47331 0" />
    <limit
      lower="-0.75"
      upper="0.01"
      effort="100"
      velocity="3" />
    <mimic
      joint="gear_1_joint_6"
      multiplier="1"
      offset="0" />
  </joint>
  <link
    name="link_5_1">
    <inertial>
      <origin
        xyz="-0.014639 0.0041145 0.020416"
        rpy="0 0 0" />
      <mass
        value="0.0015553" />
      <inertia
        ixx="2.065E-07"
        ixy="7.1279E-08"
        ixz="3.6198E-08"
        iyy="1.101E-07"
        iyz="-6.8177E-08"
        izz="1.7443E-07" />
    </inertial>
    <visual>
      <origin
        xyz="0 0 0"
        rpy="0 0 0" />
      <geometry>
        <mesh
          filename="package://roboticarm8/meshes/link_5_1.STL" />
      </geometry>
      <material
        name="">
        <color
          rgba="1 1 1 1" />
      </material>
    </visual>
    <collision>
      <origin
        xyz="0 0 0"
        rpy="0 0 0" />
      <geometry>
        <mesh
          filename="package://roboticarm8/meshes/link_5_1.STL" />
      </geometry>
    </collision>
  </link>
  <joint
    name="link_5_1_joint_9"
    type="fixed">
    <origin
      xyz="-0.010174 -0.028443 0.012806"
      rpy="-3.138 -0.0019291 -0.0049516" />
    <parent
      link="gear_2" />
    <child
      link="link_5_1" />
    <axis
      xyz="0 0 0" />
    <limit
      lower="0"
      upper="1"
      effort="100"
      velocity="3" />
    <mimic
      joint="link_5_joint_6"
      multiplier="1"
      offset="0" />
  </joint>
  <link
    name="grip_2">
    <inertial>
      <origin
        xyz="-0.017372 0.015659 -0.0021786"
        rpy="0 0 0" />
      <mass
        value="0.014256" />
      <inertia
        ixx="3.7464E-06"
        ixy="1.4458E-06"
        ixz="1.2722E-07"
        iyy="1.7909E-06"
        iyz="-2.3962E-07"
        izz="3.7283E-06" />
    </inertial>
    <visual>
      <origin
        xyz="0 0 0"
        rpy="0 0 0" />
      <geometry>
        <mesh
          filename="package://roboticarm8/meshes/grip_2.STL" />
      </geometry>
      <material
        name="">
        <color
          rgba="1 1 1 1" />
      </material>
    </visual>
    <collision>
      <origin
        xyz="0 0 0"
        rpy="0 0 0" />
      <geometry>
        <mesh
          filename="package://roboticarm8/meshes/grip_2.STL" />
      </geometry>
    </collision>
  </link>
  <joint
    name="grip_5_joint_11"
    type="fixed">
    <origin
      xyz="-0.015385 0.02258 0.029368"
      rpy="0 0 0" />
    <parent
      link="link_5_1" />
    <child
      link="grip_2" />
    <axis
      xyz="0 0 0" />
    <limit
      lower="0"
      upper="6.28319"
      effort="100"
      velocity="3" />
    <mimic
      joint="grip_1_joint_7"
      multiplier="1"
      offset="0" />
  </joint>
<transmission name="base_cap_trans">
        <type>transmission_interface/SimpleTransmission</type>
        <joint name="base_cap_joint_1">
            <hardwareInterface>hardware_interface/PositionJointInterface</hardwareInterface>
        </joint>
        <actuator name="base_cap_motor">
            <hardwareInterface>hardware_interface/PositionJointInterface</hardwareInterface>
            <mechanicalReduction>1</mechanicalReduction>
        </actuator>
    </transmission>

    <transmission name="link_1_trans">
        <type>transmission_interface/SimpleTransmission</type>
        <joint name="link_1_joint_2">
            <hardwareInterface>hardware_interface/PositionJointInterface</hardwareInterface>
        </joint>
        <actuator name="link_1_motor">
            <hardwareInterface>hardware_interface/PositionJointInterface</hardwareInterface>
            <mechanicalReduction>1</mechanicalReduction>
        </actuator>
    </transmission>

    <transmission name="link_2_trans">
        <type>transmission_interface/SimpleTransmission</type>
        <joint name="link_2_joint_3">
            <hardwareInterface>hardware_interface/PositionJointInterface</hardwareInterface>
        </joint>
        <actuator name="link_2_motor">
            <hardwareInterface>hardware_interface/PositionJointInterface</hardwareInterface>
            <mechanicalReduction>1</mechanicalReduction>
        </actuator>
    </transmission>

    <transmission name="link_3_trans">
        <type>transmission_interface/SimpleTransmission</type>
        <joint name="link_3_joint_4">
            <hardwareInterface>hardware_interface/PositionJointInterface</hardwareInterface>
        </joint>
        <actuator name="link_3_motor">
            <hardwareInterface>hardware_interface/PositionJointInterface</hardwareInterface>
            <mechanicalReduction>1</mechanicalReduction>
        </actuator>
    </transmission>

    <transmission name="link_4_trans">
        <type>transmission_interface/SimpleTransmission</type>
        <joint name="link_4_joint_5">
            <hardwareInterface>hardware_interface/PositionJointInterface</hardwareInterface>
        </joint>
        <actuator name="link_4_motor">
            <hardwareInterface>hardware_interface/PositionJointInterface</hardwareInterface>
            <mechanicalReduction>1</mechanicalReduction>
        </actuator>
    </transmission>

    <transmission name="gear_1_trans">
        <type>transmission_interface/SimpleTransmission</type>
        <joint name="gear_1_joint_6">
            <hardwareInterface>hardware_interface/PositionJointInterface</hardwareInterface>
        </joint>
        <actuator name="gear_1_motor">
            <hardwareInterface>hardware_interface/PositionJointInterface</hardwareInterface>
            <mechanicalReduction>1</mechanicalReduction>
        </actuator>
    </transmission>

    <transmission name="gear_2_trans">
        <type>transmission_interface/SimpleTransmission</type>
        <joint name="gear_2_joint_8">
            <hardwareInterface>hardware_interface/PositionJointInterface</hardwareInterface>
        </joint>
        <actuator name="gear_2_motor">
            <hardwareInterface>hardware_interface/PositionJointInterface</hardwareInterface>
            <mechanicalReduction>1</mechanicalReduction>
        </actuator>
    </transmission>
 <gazebo>
    <plugin name="gazebo_ros_control" filename="libgazebo_ros_control.so">
        <robotNamespace>/</robotNamespace>
    </plugin>
 </gazebo>

 <gazebo reference="link_1">
    <selfCollide>true</selfCollide>
 </gazebo>

 <gazebo reference="link_2">
    <selfCollide>true</selfCollide>
 </gazebo>

 <gazebo reference="link_3">
    <selfCollide>true</selfCollide>
 </gazebo>

 <gazebo reference="link_4">
    <selfCollide>true</selfCollide>
 </gazebo>

 <gazebo reference="gear_1">
    <selfCollide>true</selfCollide>
 </gazebo>

 <gazebo reference="gear_2">
    <selfCollide>true</selfCollide>
 </gazebo>
</robot>

