<?xml version="1.0"?>
<robot name="alfr3">

  <link name="base_link">
    <inertial>
      <origin xyz="0.010175 0 -0.0054305" rpy="0 0 0"/>
      <mass value="0.11564"/>
      <inertia ixx="0.00012118" ixy="0" ixz="-1.1093E-06" iyy="0.00029141" iyz="0" izz="0.0004083"/>
    </inertial>
    <visual>
      <origin xyz="0 0 0" rpy="0 0 0"/>
      <geometry>
        <mesh filename="package://alfr3/meshes/base_link.STL"/>
      </geometry>
      <material name="Blue">
        <color rgba="0.1 0.1 0.8 1"/>
      </material>
    </visual>
    <collision>
      <origin xyz="0 0 0" rpy="0 0 0"/>
      <geometry>
        <mesh filename="package://alfr3/meshes/base_link.STL"/>
      </geometry>
    </collision>
  </link>

  <link name="left_wheel">
    <inertial>
      <origin xyz="0 0 -0.02" rpy="0 0 0"/>
      <mass value="0.17114"/>
      <inertia ixx="8.1335E-05" ixy="0" ixz="0" iyy="8.1335E-05" iyz="0" izz="0.00011723"/>
    </inertial>
    <visual>
      <origin xyz="0 0 0" rpy="0 0 0"/>
      <geometry>
        <mesh filename="package://alfr3/meshes/left_wheel.STL"/>
      </geometry>
      <material name="Black">
        <color rgba="0.1 0.1 0.1 1"/>
      </material>
    </visual>
    <collision>
      <origin xyz="0 0 0" rpy="0 0 0"/>
      <geometry>
        <mesh filename="package://alfr3/meshes/left_wheel.STL"/>
      </geometry>
    </collision>
  </link>

  <link name="right_wheel">
    <inertial>
      <origin xyz="0 0 0.02" rpy="0 0 0"/>
      <mass value="0.17114"/>
      <inertia ixx="8.1335E-05" ixy="0" ixz="0" iyy="8.1335E-05" iyz="0" izz="0.00011723"/>
    </inertial>
    <visual>
      <origin xyz="0 0 0" rpy="0 0 0"/>
      <geometry>
        <mesh filename="package://alfr3/meshes/right_wheel.STL"/>
      </geometry>
      <material name="Black">
        <color rgba="0.1 0.1 0.1 1"/>
      </material>
    </visual>
    <collision>
      <origin xyz="0 0 0" rpy="0 0 0"/>
      <geometry>
        <mesh filename="package://alfr3/meshes/right_wheel.STL"/>
      </geometry>
    </collision>
  </link>

  <link name="castor_wheel">
    <inertial>
      <origin xyz="0.010175 0 -0.0054305" rpy="0 0 0"/>
      <mass value="0.11564"/>
      <inertia ixx="0.00012118" ixy="0" ixz="-1.1093E-06" iyy="0.00029141" iyz="0" izz="0.0004083"/>
    </inertial>
    <visual>
      <origin xyz="0 0 0" rpy="0 0 0"/>
      <geometry>
        <mesh filename="package://alfr3/meshes/castor_wheel.STL"/>
      </geometry>
      <material name="Black">
        <color rgba="0.1 0.1 0.1 1"/>
      </material>
    </visual>
    <collision>
      <origin xyz="0 0 0" rpy="0 0 0"/>
      <geometry>
        <mesh filename="package://alfr3/meshes/castor_wheel.STL"/>
      </geometry>
    </collision>
  </link>

  <link name="camera_link">
    <visual>
      <origin xyz="0 0 0" rpy="0 0 0"/>
      <geometry>
        <box size="0.01 0.03 0.03"/>
      </geometry>
      <material name="Grey">
        <color rgba="0.5 0.5 0.5 1"/>
      </material>
    </visual>
    <collision>
      <origin xyz="0 0 0" rpy="0 0 0"/>
      <geometry>
        <box size="0.02 0.05 0.05"/>
      </geometry>
    </collision>
    <inertial>
      <mass value="1e-5"/>
      <origin xyz="0 0 0" rpy="0 0 0"/>
      <inertia ixx="1e-6" ixy="0" ixz="0" iyy="1e-6" iyz="0" izz="1e-6"/>
    </inertial>
  </link>

  <joint name="left_wheel_joint" type="continuous">
    <origin xyz="-0.06317 0.1103 -0.004" rpy="-1.5708 0 0"/>
    <parent link="base_link"/>
    <child link="left_wheel"/>
    <axis xyz="0 0 -1"/>
  </joint>

  <joint name="right_wheel_joint" type="continuous">
    <origin xyz="-0.06317 -0.1103 -0.004" rpy="-1.5708 0 0"/>
    <parent link="base_link"/>
    <child link="right_wheel"/>
    <axis xyz="0 0 1"/>
  </joint>

  <joint name="castor_wheel_joint" type="continuous">
    <origin xyz="0.05883 0 -0.033" rpy="-1.5708 0 0"/>
    <parent link="base_link"/>
    <child link="castor_wheel"/>
    <axis xyz="0 0 -1"/>
  </joint>

  <joint name="camera_joint" type="fixed">
    <origin xyz="0.13 0 0.01" rpy="0 0.7 0"/>
    <parent link="base_link"/>
    <child link="camera_link"/>
  </joint>

  <!-- ============================ TRANSMISSIONS ============================= -->
  <transmission name="left_wheel_transmission">
    <type>transmission_interface/SimpleTransmission</type>
    <joint name="left_wheel_joint">
      <hardwareInterface>hardware_interface/VelocityJointInterface</hardwareInterface>
    </joint>
    <actuator name="left_wheel_motor">
      <hardwareInterface>hardware_interface/VelocityJointInterface</hardwareInterface>
      <mechanicalReduction>1</mechanicalReduction>
    </actuator>
  </transmission>

  <transmission name="right_wheel_transmission">
    <type>transmission_interface/SimpleTransmission</type>
    <joint name="right_wheel_joint">
      <hardwareInterface>hardware_interface/VelocityJointInterface</hardwareInterface>
    </joint>
    <actuator name="right_wheel_motor">
      <hardwareInterface>hardware_interface/VelocityJointInterface</hardwareInterface>
      <mechanicalReduction>1</mechanicalReduction>
    </actuator>
  </transmission>

  <!-- ============================== GAZEBO PLUGINS =========================== -->
  <gazebo reference="base_link">
    <material>Gazebo/Blue</material>
  </gazebo>

  <gazebo reference="left_wheel">
    <material>Gazebo/Black</material>
  </gazebo>

  <gazebo reference="right_wheel">
    <material>Gazebo/Black</material>
  </gazebo>

  <gazebo reference="castor_wheel">
    <material>Gazebo/Black</material>
  </gazebo>

  <!-- 👇 Added hardware interfaces for Gazebo -->
  <gazebo reference="left_wheel_joint">
    <hardwareInterface>hardware_interface/VelocityJointInterface</hardwareInterface>
  </gazebo>

  <gazebo reference="right_wheel_joint">
    <hardwareInterface>hardware_interface/VelocityJointInterface</hardwareInterface>
  </gazebo>
  
     <!-- Dummy link to avoid root inertia warning -->
<link name="dummy_link"/>
<joint name="base_fixed_joint" type="fixed">
  <parent link="dummy_link"/>
  <child link="base_link"/>
</joint>

  <gazebo reference="camera_link">
    <sensor name="line_camera" type="camera">
      <update_rate>30</update_rate>
      <camera name="head">
        <horizontal_fov>1.047</horizontal_fov>
        <image>
          <width>640</width>
          <height>480</height>
          <format>R8G8B8</format>
        </image>
        <clip>
          <near>0.1</near>
          <far>100</far>
        </clip>
      </camera>
      <plugin name="camera_controller" filename="libgazebo_ros_camera.so">
        <alwaysOn>true</alwaysOn>
        <updateRate>30</updateRate>
        <cameraName>line_camera</cameraName>
        <namespace>/</namespace>
        <imageTopicName>image_raw</imageTopicName>
        <cameraInfoTopicName>camera_info</cameraInfoTopicName>
        <frame_name>camera_link</frame_name>
      </plugin>
    </sensor>
  </gazebo>

  <!-- ros_control plugin -->
  <gazebo>
    <plugin name="gazebo_ros_control" filename="libgazebo_ros_control.so">
      <robotNamespace>/</robotNamespace>
    </plugin>
  </gazebo>
</robot>
