<?xml version="1.0"?>
<robot name="alfr3">
  <!-- Base Link -->
  <link name="base_link">
    <inertial>
      <origin xyz="0 0 0" rpy="0 0 0"/>
      <mass value="0.11564"/>
      <inertia ixx="0.00012118" ixy="0" ixz="0" iyy="0.00029141" iyz="0" izz="0.0004083"/>
    </inertial>
    <visual>
      <geometry>
        <mesh filename="package://alfr3/meshes/base_link.STL"/>
      </geometry>
      <material name="Blue">
        <color rgba="0 0 1 1"/>
      </material>
    </visual>
    <collision>
      <geometry>
        <mesh filename="package://alfr3/meshes/base_link.STL"/>
      </geometry>
    </collision>
  </link>

  <!-- Left Wheel -->
  <link name="left_wheel">
    <inertial>
      <origin xyz="0 0 -0.02" rpy="0 0 0"/>
      <mass value="0.17114"/>
      <inertia ixx="8.1335e-05" ixy="0" ixz="0" iyy="8.1335e-05" iyz="0" izz="0.00011723"/>
    </inertial>
    <visual>
      <geometry>
        <mesh filename="package://alfr3/meshes/left_wheel.STL"/>
      </geometry>
      <material name="Black">
        <color rgba="0 0 0 1"/>
      </material>
    </visual>
    <collision>
      <geometry>
        <mesh filename="package://alfr3/meshes/left_wheel.STL"/>
      </geometry>
    </collision>
  </link>

  <joint name="left_wheel_joint" type="continuous">
    <parent link="base_link"/>
    <child link="left_wheel"/>
    <origin xyz="-0.06317 0.1103 -0.004" rpy="-1.5708 0 0"/>
    <axis xyz="0 0 1"/>
    <limit effort="10" velocity="10"/>
    <dynamics friction="2.0" damping="0.5"/>
  </joint>

  <!-- Right Wheel -->
  <link name="right_wheel">
    <inertial>
      <origin xyz="0 0 0.02" rpy="0 0 0"/>
      <mass value="0.17114"/>
      <inertia ixx="8.1335e-05" ixy="0" ixz="0" iyy="8.1335e-05" iyz="0" izz="0.00011723"/>
    </inertial>
    <visual>
      <geometry>
        <mesh filename="package://alfr3/meshes/right_wheel.STL"/>
      </geometry>
      <material name="Black">
        <color rgba="0.3 0.3 0.3 1"/>
      </material>
    </visual>
    <collision>
      <geometry>
        <mesh filename="package://alfr3/meshes/right_wheel.STL"/>
      </geometry>
    </collision>
  </link>

  <joint name="right_wheel_joint" type="continuous">
    <parent link="base_link"/>
    <child link="right_wheel"/>
    <origin xyz="-0.06317 -0.1103 -0.004" rpy="-1.5708 0 0"/>
    <axis xyz="0 0 1"/>
    <limit effort="10" velocity="10"/>
    <dynamics friction="2.0" damping="0.5"/>
  </joint>

  <!-- Castor Wheel -->
  <link name="castor_wheel">
    <inertial>
      <origin xyz="0 0 0" rpy="0 0 0"/>
      <mass value="0.05"/>
      <inertia ixx="1e-4" ixy="0" ixz="0" iyy="1e-4" iyz="0" izz="1e-4"/>
    </inertial>
    <visual>
      <geometry>
        <mesh filename="package://alfr3/meshes/castor_wheel.STL"/>
      </geometry>
      <material name="Black">
        <color rgba="0 0 0 1"/>
      </material>
    </visual>
    <collision>
      <geometry>
        <mesh filename="package://alfr3/meshes/castor_wheel.STL"/>
      </geometry>
    </collision>
  </link>

  <joint name="castor_wheel_joint" type="fixed">
    <parent link="base_link"/>
    <child link="castor_wheel"/>
    <origin xyz="0.05883 0 -0.033" rpy="-1.5708 0 0"/>
    <axis xyz="0 0 1"/>
    <limit effort="10" velocity="10"/>
    <dynamics friction="0.1"/>
  </joint>
  
    <!-- Dummy root link -->
  <link name="dummy_link"/>
  <joint name="base_fixed_joint" type="fixed">
    <parent link="dummy_link"/>
    <child link="base_link"/>
  </joint>

  <!-- Camera -->
  <link name="camera_link">
    <inertial>
      <mass value="1e-5"/>
      <inertia ixx="1e-6" ixy="0" ixz="0" iyy="1e-6" iyz="0" izz="1e-6"/>
    </inertial>
    <visual>
      <geometry>
        <box size="0.01 0.03 0.03"/>
      </geometry>
    </visual>
    <collision>
      <geometry>
        <box size="0.02 0.05 0.05"/>
      </geometry>
    </collision>
  </link>

  <joint name="camera_joint" type="fixed">
    <parent link="base_link"/>
    <child link="camera_link"/>
    <origin xyz="0.13 0 0.01" rpy="0 0.5 0"/>
  </joint>

  <!-- Gazebo Camera Sensor -->
  <gazebo reference="camera_link">
    <sensor name="front_camera" type="camera">
      <always_on>true</always_on>
      <update_rate>30</update_rate>
      <camera>
        <horizontal_fov>1.047</horizontal_fov>
        <image>
          <width>640</width>
          <height>480</height>
          <format>R8G8B8</format>
        </image>
        <clip>
          <near>0.1</near>
          <far>200</far>
        </clip>
      </camera>
      <plugin name="camera_controller" filename="libgazebo_ros_camera.so">
        <alwaysOn>true</alwaysOn>
        <updateRate>30</updateRate>
        <cameraName>front_camera</cameraName>
        <imageTopicName>image_raw</imageTopicName>
        <cameraInfoTopicName>camera_info</cameraInfoTopicName>
        <frameName>camera_link</frameName>
      </plugin>
    </sensor>
  </gazebo>

  <!-- Gazebo Materials -->
  <gazebo reference="base_link">
    <material>Gazebo/Blue</material>
  </gazebo>
  <gazebo reference="left_wheel">
    <material>Gazebo/Black</material>
  </gazebo>
  <gazebo reference="right_wheel">
    <material>Gazebo/Black</material>
  </gazebo>
  <gazebo reference="castor_wheel">
    <material>Gazebo/Black</material>
  </gazebo>

  <!-- Wheel Transmissions -->
  <transmission name="left_wheel_transmission">
    <type>transmission_interface/SimpleTransmission</type>
    <joint name="left_wheel_joint">
      <hardwareInterface>hardware_interface/VelocityJointInterface</hardwareInterface>
    </joint>
    <actuator name="left_wheel_motor">
      <hardwareInterface>hardware_interface/VelocityJointInterface</hardwareInterface>
      <mechanicalReduction>1</mechanicalReduction>
    </actuator>
  </transmission>

  <transmission name="right_wheel_transmission">
    <type>transmission_interface/SimpleTransmission</type>
    <joint name="right_wheel_joint">
      <hardwareInterface>hardware_interface/VelocityJointInterface</hardwareInterface>
    </joint>
    <actuator name="right_wheel_motor">
      <hardwareInterface>hardware_interface/VelocityJointInterface</hardwareInterface>
      <mechanicalReduction>1</mechanicalReduction>
    </actuator>
  </transmission>

  <!-- Gazebo ros_control plugin -->
  <gazebo>
    <plugin name="gazebo_ros_control" filename="libgazebo_ros_control.so">
      <robotNamespace></robotNamespace>
    </plugin>
  </gazebo>

</robot>

