<?xml version="1.0" encoding="utf-8"?>
<robot
  name="alfr3">
    <!-- Dummy root link -->
  <link name="dummy_link"/>
  <joint name="base_fixed_joint" type="fixed">
    <parent link="dummy_link"/>
    <child link="base_link"/>
    <origin xyz="0 0 0" rpy="0 0 0"/>
  </joint>
  <link
    name="base_link">
    <inertial>
      <origin
        xyz="0.0101750610475537 3.01162104856261E-11 -0.00543051302823661"
        rpy="0 0 0" />
      <mass
        value="0.115638449795906" />
      <inertia
        ixx="0.000121183436612198"
        ixy="-1.63442253633623E-11"
        ixz="-1.10928051959097E-06"
        iyy="0.000291410349126256"
        iyz="1.11704603442676E-16"
        izz="0.000408303216402241" />
    </inertial>
    <visual>
      <origin
        xyz="0 0 0"
        rpy="0 0 0" />
      <geometry>
        <mesh
          filename="package://alfr3/meshes/base_link.STL" />
      </geometry>
      <material
        name="">
        <color
          rgba="1 1 1 1" />
      </material>
    </visual>
    <collision>
      <origin
        xyz="0 0 0"
        rpy="0 0 0" />
      <geometry>
        <mesh
          filename="package://alfr3/meshes/base_link.STL" />
      </geometry>
    </collision>
  </link>
  <link
    name="left_wheel">
    <inertial>
      <origin
        xyz="0 8.6736E-18 -0.02"
        rpy="0 0 0" />
      <mass
        value="0.17114" />
      <inertia
        ixx="8.1335E-05"
        ixy="1.8375E-22"
        ixz="2.264E-21"
        iyy="8.1335E-05"
        iyz="-2.7578E-21"
        izz="0.00011723" />
    </inertial>
    <visual>
      <origin
        xyz="0 0 0"
        rpy="0 0 0" />
      <geometry>
        <mesh
          filename="package://alfr3/meshes/left_wheel.STL" />
      </geometry>
      <material
        name="">
        <color
          rgba="0.29804 0.29804 0.29804 1" />
      </material>
    </visual>
    <collision>
      <origin
        xyz="0 0 0"
        rpy="0 0 0" />
      <geometry>
        <mesh
          filename="package://alfr3/meshes/left_wheel.STL" />
      </geometry>
    </collision>
  </link>
  <joint
    name="left_wheel_joint"
    type="continuous">
    <origin
      xyz="-0.06317 0.1103 -0.004"
      rpy="-1.5708 0 0" />
    <parent
      link="base_link" />
    <child
      link="left_wheel" />
    <axis
      xyz="0 0 1" />
    <limit
      effort="10"
      velocity="10" />
    <dynamics
      friction="0.1" />
  </joint>
  <link
    name="right_wheel">
    <inertial>
      <origin
        xyz="0 8.8905E-18 0.02"
        rpy="0 0 0" />
      <mass
        value="0.17114" />
      <inertia
        ixx="8.1335E-05"
        ixy="1.8376E-22"
        ixz="-2.2676E-21"
        iyy="8.1335E-05"
        iyz="2.4665E-21"
        izz="0.00011723" />
    </inertial>
    <visual>
      <origin
        xyz="0 0 0"
        rpy="0 0 0" />
      <geometry>
        <mesh
          filename="package://alfr3/meshes/right_wheel.STL" />
      </geometry>
      <material
        name="">
        <color
          rgba="0.29804 0.29804 0.29804 1" />
      </material>
    </visual>
    <collision>
      <origin
        xyz="0 0 0"
        rpy="0 0 0" />
      <geometry>
        <mesh
          filename="package://alfr3/meshes/right_wheel.STL" />
      </geometry>
    </collision>
  </link>
  <joint
    name="right_wheel_joint"
    type="continuous">
    <origin
      xyz="-0.06317 -0.1103 -0.004"
      rpy="-1.5708 0 0" />
    <parent
      link="base_link" />
    <child
      link="right_wheel" />
    <axis
      xyz="0 0 1" />
    <limit
      effort="10"
      velocity="10" />
    <dynamics
      friction="0.1" />
  </joint>
  <link
    name="castor_wheel">
    <inertial>
      <origin
        xyz="0.010175 3.0116E-11 -0.0054305"
        rpy="0 0 0" />
      <mass
        value="0.11564" />
      <inertia
        ixx="0.00012118"
        ixy="-1.6344E-11"
        ixz="-1.1093E-06"
        iyy="0.00029141"
        iyz="1.117E-16"
        izz="0.0004083" />
    </inertial>
    <visual>
      <origin
        xyz="0 0 0"
        rpy="0 0 0" />
      <geometry>
        <mesh
          filename="package://alfr3/meshes/castor_wheel.STL" />
      </geometry>
      <material
        name="">
        <color
          rgba="1 1 1 1" />
      </material>
    </visual>
    <collision>
      <origin
        xyz="0 0 0"
        rpy="0 0 0" />
      <geometry>
        <mesh
          filename="package://alfr3/meshes/castor_wheel.STL" />
      </geometry>
    </collision>
  </link>
  <joint
    name="castor_wheel_joint"
    type="continuous">
    <origin
      xyz="0.05883 0 -0.033"
      rpy="-1.5708 0 0" />
    <parent
      link="base_link" />
    <child
      link="castor_wheel" />
    <axis
      xyz="0 0 1" />
    <limit
      lower="0"
      upper="0"
      effort="10"
      velocity="10" />
    <dynamics
      friction="0.1" />
  </joint>
    <link name="camera_link">
    <inertial>
      <mass value="1e-5"/>
      <inertia ixx="1e-6" ixy="0" ixz="0"
               iyy="1e-6" iyz="0" izz="1e-6"/>
    </inertial>

    <visual>
      <geometry>
        <box size="0.01 0.03 0.03"/>
      </geometry>
    </visual>

    <collision>
      <geometry>
        <box size="0.02 0.05 0.05"/>
      </geometry>
    </collision>
  </link>

  <joint name="camera_joint" type="fixed">
    <parent link="base_link"/>
    <child link="camera_link"/>
    <origin xyz="0.13 0 0.01" rpy="0 0.5 0"/>
  </joint>

  <gazebo reference="camera_link">
  <sensor name="front_camera" type="camera">
    <always_on>true</always_on>
    <update_rate>30</update_rate>
    <camera>
      <horizontal_fov>1.047</horizontal_fov>
      <image>
        <width>640</width>
        <height>480</height>
        <format>R8G8B8</format>
      </image>
      <clip>
        <near>0.1</near>
        <far>200</far>
      </clip>
    </camera>
    <plugin name="camera_controller" filename="libgazebo_ros_camera.so">
      <alwaysOn>true</alwaysOn>
      <updateRate>30</updateRate>
      <cameraName>front_camera</cameraName>
      <imageTopicName>image_raw</imageTopicName>
      <cameraInfoTopicName>camera_info</cameraInfoTopicName>
      <frameName>camera_link</frameName>
    </plugin>
  </sensor>
</gazebo>

</robot>
